<?xml version="1.0" ?>
<robot name="spot" xmlns:xacro="http://www.ros.org/wiki/xacro">
<!-- Body -->
        <link name="body">
        <visual>
            <geometry>
                <mesh filename="package://rs_description/meshes/body.dae" />
            </geometry>
        </visual>
        <collision>
            <geometry>
                <mesh filename="package://rs_description/meshes/body_collision.stl" />
            </geometry>
        </collision>
        <inertial>
             <mass value="16.25" />
             <inertia  ixx="0.085" ixy="0.0"  ixz="0.0"  iyy="1.045"  iyz="0.0"  izz="1.042" />
    	</inertial>
    </link>
<!-- Base link -->
    <link name="base_link"/>
    <joint name="base_link_joint" type="fixed">
        <origin xyz="0 0 0" rpy="0 0 0" />
        <parent link="body" />
        <child link="base_link" />
    </joint>
<!-- Front rail -->
    <link name="front_rail"/>
    <joint name="front_rail_joint" type="fixed">
        <origin xyz="0.223 0 0.04505" rpy="0 0 0" />
        <parent link="body" />
        <child link="front_rail" />
    </joint>
<!-- Rear rail -->
    <link name="rear_rail"/>
    <joint name="rear_rail_joint" type="fixed">
        <origin xyz="-0.223 0 0.04505" rpy="0 0 0" />
        <parent link="body" />
        <child link="rear_rail" />
    </joint> 
<!-- front_left_hip -->
    <link name="front_left_hip">
        <visual>
            <geometry>
                <mesh filename="package://rs_description/meshes/front_left_hip.dae" />
            </geometry>
        </visual>
        <collision>
            <geometry>
                <mesh filename="package://rs_description/meshes/front_left_hip_collision.stl" />
            </geometry>
        </collision>
        <inertial>
            <mass value="1.5" />
    	    <inertia  ixx="0.0605" ixy="0.0"  ixz="0.0"  iyy="0.0"  iyz="0.0"  izz="0.0" />
    	</inertial>
    </link>
    
    <joint name="front_left_hip_x" type="revolute">
        <origin xyz="0.29785 0.05500 0.00000" rpy="0 0 0" />
        <axis xyz="1 0 0" />
        <parent link="body" />
	<child link="front_left_hip" />
	<dynamics damping="0.1" friction="0.1"/>
        <limit effort="1000" velocity="1000.00" lower="-0.78539816339744827899" upper="0.78539816339744827899" />
    </joint>
    
    <transmission name="front_left_hip_x_trans">
	  <type>transmission_interface/SimpleTransmission</type>
	  <joint name="front_left_hip_x">
          	<hardwareInterface>hardware_interface/EffortJointInterface</hardwareInterface>
          </joint>
	  <actuator name="front_left_hip_x">
          	<mechanicalReduction>50</mechanicalReduction>
          	<hardwareInterface>hardware_interface/EffortJointInterface</hardwareInterface>
	  </actuator>
    </transmission>
<!-- front_left_upper_leg -->
    <link name="front_left_upper_leg">
        <visual>
            <geometry>
                <mesh filename="package://rs_description/meshes/front_left_upper_leg.dae" />
            </geometry>
        </visual>
        <collision>
            <geometry>
                <mesh filename="package://rs_description/meshes/front_left_upper_leg_collision.stl" />
            </geometry>
        </collision>
        <inertial>
            <mass value="1.5" />
    	    <inertia  ixx="0.0" ixy="0.0"  ixz="0.0"  iyy="0.05"  iyz="0.0"  izz="0.0" />
    	</inertial>
    </link>
    
    <joint name="front_left_hip_y" type="revolute">
        <origin xyz="0.0 0.110945 0.0" rpy="0 0 0" />
        <axis xyz="0 1 0" />
        <parent link="front_left_hip" />
	<child link="front_left_upper_leg" />
	<dynamics damping="0.1" friction="0.1"/>
        <limit effort="1000" velocity="1000.00" lower="-0.89884456477707963539" upper="2.2951079663725435509" />
    </joint>

    <transmission name="front_left_hip_y_trans">
	  <type>transmission_interface/SimpleTransmission</type>
	  <joint name="front_left_hip_y">
          	<hardwareInterface>hardware_interface/EffortJointInterface</hardwareInterface>
          </joint>
	  <actuator name="front_left_hip_y">
          	<mechanicalReduction>50</mechanicalReduction>
          	<hardwareInterface>hardware_interface/EffortJointInterface</hardwareInterface>
	  </actuator>
    </transmission>
<!-- front_left_lower_leg -->   
    <link name="front_left_lower_leg">
        <visual>
            <geometry>
                <mesh filename="package://rs_description/meshes/front_left_lower_leg.dae" />
            </geometry>
        </visual>
        <collision name="front_left_lower_leg_fixed_joint_lump__front_bump_sensor">
            <geometry>
                <mesh filename="package://rs_description/meshes/front_left_lower_leg_collision.stl" />
            </geometry>
        </collision>
        <inertial>right
            <mass value="1.0" />
    	    <inertia  ixx="0.0" ixy="0.0"  ixz="0.0"  iyy="0.045"  iyz="0.0"  izz="0.0" />
    	</inertial>
    </link>

    <joint name="front_left_knee" type="revolute">
        <origin xyz="0.025 0.000 -0.3205" rpy="0 0 0" />
        <axis xyz="0 1 0" />
        <parent link="front_left_upper_leg" />
        <child link="front_left_lower_leg" />
        <dynamics damping="0.1" friction="0.1"/>
        <limit effort="1000" velocity="1000.00" lower="-2.7929" upper="-0.254801" />
    </joint>

     <!-- Contact Sensor -->
  <gazebo reference="front_left_lower_leg">
    <sensor name="front_left_lower_leg_contactsensor_sensor" type="contact">
      <always_on>true</always_on>
      <contact>
        <collision>front_left_lower_leg_fixed_joint_lump__front_bump_sensor_collision</collision>
      </contact>
      <plugin filename="libgazebo_ros_bumper.so" name="front_left_lower_leg_plugin">
        <bumperTopicName>front_left_lower_leg_contact</bumperTopicName>
        <frameName>front_left_lower_leg</frameName>
      </plugin>
    </sensor>
  </gazebo>

    <transmission name="front_left_knee_trans">
	  <type>transmission_interface/SimpleTransmission</type>
	  <joint name="front_left_knee">
          	<hardwareInterface>hardware_interface/EffortJointInterface</hardwareInterface>
          </joint>
	  <actuator name="front_left_knee">
          	<mechanicalReduction>50</mechanicalReduction>
          	<hardwareInterface>hardware_interface/EffortJointInterface</hardwareInterface>
	  </actuator>
    </transmission>
<!--front_right_hip-->
    <link name="front_right_hip">
        <visual>
            <geometry>
                <mesh filename="package://rs_description/meshes/front_right_hip.dae" />
            </geometry>
        </visual>
        <collision>
            <geometry>
                <mesh filename="package://rs_description/meshes/front_right_hip_collision.stl" />
            </geometry>
        </collision>
        <inertial>
            <mass value="1.5" />
    	    <inertia  ixx="0.0605" ixy="0.0"  ixz="0.0"  iyy="0.0"  iyz="0.0"  izz="0.0" />
    	</inertial>
    </link>

    <joint name="front_right_hip_x" type="revolute">
        <origin xyz="0.29785 -0.05500 0.00000" rpy="0 0 0" />
        <axis xyz="1 0 0" />
        <parent link="body" />
        <child link="front_right_hip" />
        <dynamics damping="0.1" friction="0.1"/>
        <limit effort="1000" velocity="1000.00" lower="-0.78539816339744827899" upper="0.78539816339744827899" />
    </joint>

    <transmission name="front_right_hip_x_trans">
	  <type>transmission_interface/SimpleTransmission</type>
	  <joint name="front_right_hip_x">
          	<hardwareInterface>hardware_interface/EffortJointInterface</hardwareInterface>
          </joint>
	  <actuator name="front_right_hip_x">
          	<mechanicalReduction>50</mechanicalReduction>
          	<hardwareInterface>hardware_interface/EffortJointInterface</hardwareInterface>
	  </actuator>
    </transmission>
<!-- front_right_upper_leg -->
    <link name="front_right_upper_leg">
        <visual>
            <geometry>
                <mesh filename="package://rs_description/meshes/front_right_upper_leg.dae" />
            </geometry>
        </visual>
        <collision>
            <geometry>
                <mesh filename="package://rs_description/meshes/front_right_upper_leg_collision.stl" />
            </geometry>
        </collision>
        <inertial>
            <mass value="1.5" />
    	    <inertia  ixx="0.0" ixy="0.0"  ixz="0.0"  iyy="0.05"  iyz="0.0"  izz="0.0" />
    	</inertial>
    </link>

    <joint name="front_right_hip_y" type="revolute">
        <origin xyz="0.0 -0.110945 0.0" rpy="0 0 0" />
        <axis xyz="0 1 0" />
        <parent link="front_right_hip" />
        <child link="front_right_upper_leg" />
        <dynamics damping="0.1" friction="0.1"/>
        <limit effort="1000" velocity="1000.00" lower="-0.89884456477707963539" upper="2.2951079663725435509" />
    </joint>

    <transmission name="front_right_hip_y_trans">
	  <type>transmission_interface/SimpleTransmission</type>
	  <joint name="front_right_hip_y">
          	<hardwareInterface>hardware_interface/EffortJointInterface</hardwareInterface>
          </joint>
	  <actuator name="front_right_hip_y">
          	<mechanicalReduction>50</mechanicalReduction>
          	<hardwareInterface>hardware_interface/EffortJointInterface</hardwareInterface>
	  </actuator>
    </transmission>
<!-- front_right_lower_leg -->
    <link name="front_right_lower_leg">
        <visual>
            <geometry>
                <mesh filename="package://rs_description/meshes/front_right_lower_leg.dae" />
            </geometry>
        </visual>
        <collision name="front_right_lower_leg_fixed_joint_lump__front_bump_sensor">
            <geometry>
                <mesh filename="package://rs_description/meshes/front_right_lower_leg_collision.stl" />
            </geometry>
        </collision>
        <inertial>
            <mass value="1.0" />
    	    <inertia  ixx="0.0" ixy="0.0"  ixz="0.0"  iyy="0.045"  iyz="0.0"  izz="0.0" />
    	</inertial>
    </link>

    <joint name="front_right_knee" type="revolute">
        <origin xyz="0.025 0.000 -0.3205" rpy="0 0 0" />
        <axis xyz="0 1 0" />
        <parent link="front_right_upper_leg" />
        <child link="front_right_lower_leg" />
        <dynamics damping="0.1" friction="0.1"/>
        <limit effort="1000" velocity="1000.00" lower="-2.7929" upper="-0.247563" />
    </joint>

     <!-- Contact Sensor -->
  <gazebo reference="front_right_lower_leg">
    <sensor name="front_right_lower_leg_contactsensor_sensor" type="contact">
      <always_on>true</always_on>
      <contact>
        <collision>front_right_lower_leg_fixed_joint_lump__front_bump_sensor_collision</collision>
      </contact>
      <plugin filename="libgazebo_ros_bumper.so" name="front_right_lower_leg_plugin">
        <bumperTopicName>front_right_lower_leg_contact</bumperTopicName>
        <frameName>front_right_lower_leg</frameName>
      </plugin>
    </sensor>
  </gazebo>

    <transmission name="front_right_knee_trans">
	  <type>transmission_interface/SimpleTransmission</type>
	  <joint name="front_right_knee">
          	<hardwareInterface>hardware_interface/EffortJointInterface</hardwareInterface>
          </joint>
	  <actuator name="front_right_knee">
          	<mechanicalReduction>50</mechanicalReduction>
          	<hardwareInterface>hardware_interface/EffortJointInterface</hardwareInterface>
	  </actuator>
    </transmission>
<!-- rear_left_hip -->
   <link name="rear_left_hip">
        <visual>
            <geometry>
                <mesh filename="package://rs_description/meshes/rear_left_hip.dae" />
            </geometry>
        </visual>
        <collision>
            <geometry>
                <mesh filename="package://rs_description/meshes/rear_left_hip_collision.stl" />
            </geometry>
        </collision>
        <inertial>
            <mass value="1.5" />
    	    <inertia  ixx="0.0605" ixy="0.0"  ixz="0.0"  iyy="0.0"  iyz="0.0"  izz="0.0" />
    	</inertial>
    </link>

    <joint name="rear_left_hip_x" type="revolute">
        <origin xyz="-0.29785 0.05500 0.00000" rpy="0 0 0" />
        <axis xyz="1 0 0" />
        <parent link="body" />
        <child link="rear_left_hip" />
        <dynamics damping="0.1" friction="0.1"/>
        <limit effort="1000" velocity="1000.00" lower="-0.78539816339744827899" upper="0.78539816339744827899" />
    </joint>

    <transmission name="rear_left_hip_x_trans">
	  <type>transmission_interface/SimpleTransmission</type>
	  <joint name="rear_left_hip_x">
          	<hardwareInterface>hardware_interface/EffortJointInterface</hardwareInterface>
          </joint>
	  <actuator name="rear_left_hip_x">
          	<mechanicalReduction>50</mechanicalReduction>
          	<hardwareInterface>hardware_interface/EffortJointInterface</hardwareInterface>
	  </actuator>
    </transmission>
<!-- rear_left_upper_leg -->
    <link name="rear_left_upper_leg">
        <visual>
            <geometry>
                <mesh filename="package://rs_description/meshes/rear_left_upper_leg.dae" />
            </geometry>
        </visual>
        <collision>
            <geometry>
                <mesh filename="package://rs_description/meshes/rear_left_upper_leg_collision.stl" />
            </geometry>
        </collision>
        <inertial>
           <mass value="1.5" />
    	   <inertia  ixx="0.0" ixy="0.0"  ixz="0.0"  iyy="0.05"  iyz="0.0"  izz="0.0" />
    	</inertial>
    </link>

    <joint name="rear_left_hip_y" type="revolute">
        <origin xyz="0.0 0.110945 0.0" rpy="0 0 0" />
        <axis xyz="0 1 0" />
        <parent link="rear_left_hip" />
        <child link="rear_left_upper_leg" />
        <dynamics damping="0.1" friction="0.1"/>
        <limit effort="1000" velocity="1000.00" lower="-0.89884456477707963539" upper="2.2951079663725435509" />
    </joint>

    <transmission name="rear_left_hip_y_trans">
	  <type>transmission_interface/SimpleTransmission</type>
	  <joint name="rear_left_hip_y">
          	<hardwareInterface>hardware_interface/EffortJointInterface</hardwareInterface>
          </joint>
	  <actuator name="rear_left_hip_y">
          	<mechanicalReduction>50</mechanicalReduction>
          	<hardwareInterface>hardware_interface/EffortJointInterface</hardwareInterface>
	  </actuator>
    </transmission>
<!-- rear_left_lower_leg -->
    <link name="rear_left_lower_leg">
        <visual>
            <geometry>
                <mesh filename="package://rs_description/meshes/rear_left_lower_leg.dae" />
            </geometry>
        </visual>
        <collision name="rear_left_lower_leg_fixed_joint_lump__rear_bump_sensor">
            <geometry>
                <mesh filename="package://rs_description/meshes/rear_left_lower_leg_collision.stl" />
            </geometry>
        </collision>
        <inertial>
            <mass value="1.0" />
    	    <inertia  ixx="0.0" ixy="0.0"  ixz="0.0"  iyy="0.045"  iyz="0.0"  izz="0.0" />
    	</inertial>
    </link>

    <joint name="rear_left_knee" type="revolute">
        <origin xyz="0.025 0.000 -0.3205" rpy="0 0 0" />
        <axis xyz="0 1 0" />
        <parent link="rear_left_upper_leg" />
        <child link="rear_left_lower_leg" />
        <dynamics damping="0.1" friction="0.1"/>
        <limit effort="1000" velocity="1000.00" lower="-2.7929" upper="-0.267153" />
    </joint>

     <!-- Contact Sensor -->
  <gazebo reference="rear_left_lower_leg">
    <sensor name="rear_left_lower_leg_contactsensor_sensor" type="contact">
      <always_on>true</always_on>
      <contact>
        <collision>rear_left_lower_leg_fixed_joint_lump__rear_bump_sensor_collision</collision>
      </contact>
      <plugin filename="libgazebo_ros_bumper.so" name="rear_left_lower_leg_plugin">
        <bumperTopicName>rear_left_lower_leg_contact</bumperTopicName>
        <frameName>rear_left_lower_leg</frameName>
      </plugin>
    </sensor>
  </gazebo>

    <transmission name="rear_left_knee_trans">
	  <type>transmission_interface/SimpleTransmission</type>
	  <joint name="rear_left_knee">
          	<hardwareInterface>hardware_interface/EffortJointInterface</hardwareInterface>
          </joint>
	  <actuator name="rear_left_knee">
          	<mechanicalReduction>50</mechanicalReduction>
          	<hardwareInterface>hardware_interface/EffortJointInterface</hardwareInterface>
	  </actuator>
    </transmission>
<!-- rear_right_hip -->
   <link name="rear_right_hip">
        <visual>
            <geometry>
                <mesh filename="package://rs_description/meshes/rear_right_hip.dae" />
            </geometry>
        </visual>
        <collision>
            <geometry>
                <mesh filename="package://rs_description/meshes/rear_right_hip_collision.stl" />
            </geometry>
        </collision>
        <inertial>
            <mass value="1.5" />
    	    <inertia  ixx="0.0605" ixy="0.0"  ixz="0.0"  iyy="0.0"  iyz="0.0"  izz="0.0" />
    	</inertial>
    </link>

    <joint name="rear_right_hip_x" type="revolute">
        <origin xyz="-0.29785 -0.05500 0.00000" rpy="0 0 0" />
        <axis xyz="1 0 0" />
        <parent link="body" />
        <child link="rear_right_hip" />
        <dynamics damping="0.1" friction="0.1"/>
        <limit effort="1000" velocity="1000.00" lower="-0.78539816339744827899" upper="0.78539816339744827899" />
    </joint>

    <transmission name="rear_right_hip_x_trans">
	  <type>transmission_interface/SimpleTransmission</type>
	  <joint name="rear_right_hip_x">
          	<hardwareInterface>hardware_interface/EffortJointInterface</hardwareInterface>
          </joint>
	  <actuator name="rear_right_hip_x">
          	<mechanicalReduction>50</mechanicalReduction>
          	<hardwareInterface>hardware_interface/EffortJointInterface</hardwareInterface>
	  </actuator>
    </transmission>
<!-- rear_right_upper_leg -->
    <link name="rear_right_upper_leg">
        <visual>
            <geometry>
                <mesh filename="package://rs_description/meshes/rear_right_upper_leg.dae" />
            </geometry>
        </visual>
        <collision>
            <geometry>
                <mesh filename="package://rs_description/meshes/rear_right_upper_leg_collision.stl" />
            </geometry>
        </collision>
        <inertial>
            <mass value="1.5" />
    	    <inertia  ixx="0.0" ixy="0.0"  ixz="0.0"  iyy="0.05"  iyz="0.0"  izz="0.0" />
    	</inertial>
    </link>

    <joint name="rear_right_hip_y" type="revolute">
        <origin xyz="0.0 -0.110945 0.0" rpy="0 0 0" />
        <axis xyz="0 1 0" />
        <parent link="rear_right_hip" />
        <child link="rear_right_upper_leg" />
        <dynamics damping="0.1" friction="0.1"/>
        <limit effort="1000" velocity="1000.00" lower="-0.89884456477707963539" upper="2.2951079663725435509" />
    </joint>

    <transmission name="rear_right_hip_y_trans">
	  <type>transmission_interface/SimpleTransmission</type>
	  <joint name="rear_right_hip_y">
          	<hardwareInterface>hardware_interface/EffortJointInterface</hardwareInterface>
          </joint>
	  <actuator name="rear_right_hip_y">
          	<mechanicalReduction>50</mechanicalReduction>
          	<hardwareInterface>hardware_interface/EffortJointInterface</hardwareInterface>
	  </actuator>
    </transmission>
<!-- rear_right_lower_leg -->
    <link name="rear_right_lower_leg">
        <visual>
            <geometry>
                <mesh filename="package://rs_description/meshes/rear_right_lower_leg.dae" />
            </geometry>
        </visual>
        <collision name='rear_right_lower_leg_fixed_joint_lump__rear_bump_sensor'>
            <geometry>
                <mesh filename="package://rs_description/meshes/rear_right_lower_leg_collision.stl" />
            </geometry>
        </collision>
        <inertial>
            <mass value="1.0" />
    	    <inertia  ixx="0.0" ixy="0.0"  ixz="0.0"  iyy="0.045"  iyz="0.0"  izz="0.0" />
    	</inertial>
    </link>

    <joint name="rear_right_knee" type="revolute">
        <origin xyz="0.025 0.000 -0.3205" rpy="0 0 0" />
        <axis xyz="0 1 0" />
        <parent link="rear_right_upper_leg" />
        <child link="rear_right_lower_leg" />
        <dynamics damping="0.1" friction="0.1"/>
        <limit effort="1000" velocity="1000.00" lower="-2.7929" upper="-0.257725" />
    </joint>

  <!-- Contact Sensor -->
  <gazebo reference="rear_right_lower_leg">
    <sensor name="rear_right_lower_leg_contactsensor_sensor" type="contact">
      <always_on>true</always_on>
      <contact>
        <collision>rear_right_lower_leg_fixed_joint_lump__rear_bump_sensor_collision</collision>
      </contact>
      <plugin filename="libgazebo_ros_bumper.so" name="rear_right_lower_leg_plugin">
        <bumperTopicName>rear_right_lower_leg_contact</bumperTopicName>
        <frameName>rear_right_lower_leg</frameName>
      </plugin>
    </sensor>
  </gazebo>

    <transmission name="rear_right_knee_trans">
	  <type>transmission_interface/SimpleTransmission</type>
	  <joint name="rear_right_knee">
          	<hardwareInterface>hardware_interface/EffortJointInterface</hardwareInterface>
          </joint>
	  <actuator name="rear_right_knee">
          	<mechanicalReduction>50</mechanicalReduction>
          	<hardwareInterface>hardware_interface/EffortJointInterface</hardwareInterface>
	  </actuator>
    </transmission>

    <gazebo>
    	<plugin name="gazebo_ros_control" filename="libgazebo_ros_control.so">
<!--    	<robotNamespace>/spot1</robotNamespace>-->
  	    </plugin>
    </gazebo>






    <!--  LOGICAL CAMERA    -->
  <!-- <xacro:include filename="$(find logical_camera)/urdf/sensors/sensor_logical_camera.urdf.xacro"/> -->
   
    <gazebo reference="rot_laser_link">
      <sensor name="logical_camera" type="logical_camera">
        <!-- <pose>0 0 0 0 1.5707 0</pose> -->
        <plugin name="logical_camera_plugin" filename="liblogical_camera.so"/>
          <!-- <topicName>/spot1/logical_camera</topicName> -->
          <logical_camera>
            <near>0.001</near>
            <far>15</far>
            <horizontal_fov>${0.2*3.1415/180.0}</horizontal_fov>
            <aspect_ratio>1.0</aspect_ratio>
          </logical_camera>

          <visualize>true</visualize>
          <always_on>true</always_on>
          <update_rate>200</update_rate>
      </sensor>  
    </gazebo>

  <!-- <joint name="lc_velodyne_joint" type="fixed">
	<origin xyz="0.125 0.0 0.001" rpy="0 0 0"/>
	<axis xyz="0 0 1"/>
	<parent link="front_rail"/>
	<child link="rot_camera_base_link"/>
  </joint>

  <link name="rot_camera_base_link">
    <inertial>
        <mass value="0.01" />
        <inertia ixx="0.0002835" ixy="0.0" ixz="0.0" iyy="0.0002835" iyz="0.0" izz="0.000324" />
    </inertial>
    <collision>
      <geometry>
        <cylinder length="0.1" radius="0.03"/>
      </geometry>
    </collision>
    <visual>
      <geometry>
        <cylinder length="0.1" radius="0.03"/>
      </geometry>
    </visual>
  </link>

  <link name="rot_camera_link">
    <inertial>
        <mass value="0.01" />
        <inertia ixx="0.0002835" ixy="0.0" ixz="0.0" iyy="0.0002835" iyz="0.0" izz="0.000324" />
    </inertial>
    <origin rpy="0.0 0.0 0.0" xyz="0.0 0.0 0.0" />
    <collision>
      <geometry>
        <mesh filename="package://rs_description/meshes/hokuyo.dae"/>
      </geometry>
    </collision>
    <visual>
      <geometry>
        <mesh filename="package://rs_description/meshes/hokuyo.dae"/>
      </geometry>
    </visual>
  </link>

  <joint name="base_to_camera_joint" type="continuous">
    <parent link="rot_camera_base_link"/>
    <child link="rot_camera_link"/>
    <axis xyz="1 0 0"/>
    <origin xyz="0.0 0.0 0.075" rpy="0.0 1.5707 0.0"/>
  </joint>  

  <transmission name="base_to_camera_trans">
    <type>transmission_interface/SimpleTransmission</type>
    <actuator name="motor1">
      <mechanicalReduction>1</mechanicalReduction>
    </actuator>
    <joint name="base_to_camera_joint">
      <hardwareInterface>EffortJointInterface</hardwareInterface>
    </joint>
  </transmission>
-->




  <!-- Rotating Laser -->  
  <joint name="velodyne_joint" type="fixed">
	<origin xyz="0.125 0.0 0.001" rpy="0 0 0"/>
	<axis xyz="0 0 1"/>
	<parent link="front_rail"/>
	<child link="rot_laser_base_link"/>
  </joint>


  <link name="rot_laser_base_link">
    <inertial>
        <mass value="0.0001" />
        <inertia ixx="0.0002835" ixy="0.0" ixz="0.0" iyy="0.0002835" iyz="0.0" izz="0.000324" />
    </inertial>
    <collision>
      <geometry>
        <cylinder length="0.1" radius="0.03"/>
      </geometry>
    </collision>
    <visual>
      <geometry>
        <cylinder length="0.1" radius="0.03"/>
      </geometry>
    </visual>
  </link>

  <link name="rot_laser_link">
    <inertial>
        <mass value="0.0001" />
        <inertia ixx="0.0002835" ixy="0.0" ixz="0.0" iyy="0.0002835" iyz="0.0" izz="0.000324" />
    </inertial>
    <origin rpy="0.0 0.0 0.0" xyz="0.0 0.0 0.0" />
    <collision>
      <geometry>
        <mesh filename="package://rs_description/meshes/hokuyo4.dae"/>
      </geometry>
    </collision>
    <visual>
      <geometry>
        <mesh filename="package://rs_description/meshes/hokuyo4.dae"/>
      </geometry>
    </visual>
  </link>

  <joint name="base_to_laser_joint" type="continuous">
    <parent link="rot_laser_base_link"/>
    <child link="rot_laser_link"/>
    <axis xyz="0 0 -1"/>
    <origin xyz="0.0 0.0 0.075" rpy="0.0 0.0 0.0"/>
  </joint> 


  <!-- the transmission for the joint of the rotating laser -->
  <transmission name="base_to_laser_trans">
    <type>transmission_interface/SimpleTransmission</type>
    <actuator name="motor1">
      <mechanicalReduction>1</mechanicalReduction>
    </actuator>
    <joint name="base_to_laser_joint">
      <hardwareInterface>hardware_interface/EffortJointInterface</hardwareInterface>
    </joint>
  </transmission>
  
  
  <gazebo reference="rot_laser_link">
    <sensor type="ray" name="head_hokuyo_sensor">
        <pose>0 0 0 0 0 0</pose>
        <visualize>true</visualize>
        <update_rate>420</update_rate>
        <ray>
            <scan>
                <horizontal>
                    <samples>1</samples>
                    <resolution>1</resolution>
                    <min_angle>-0.00110001</min_angle>
                    <max_angle>0.00100001</max_angle>
                </horizontal>
                <vertical>
                    <samples>1</samples>
                    <resolution>1</resolution>
                    <min_angle>0</min_angle>
                    <max_angle>0</max_angle>
                </vertical>
            </scan>
            <range>
                <min>0.10</min>
                <max>10.0</max>
                <resolution>0.01</resolution>
            </range>
            <noise>
                <type>gaussian</type>
                <mean>0.0</mean>
                <stddev>0.01</stddev>
            </noise>
      </ray>

        <plugin name="gazebo_ros_head_hokuyo_controller" filename="libgazebo_ros_laser.so">
          <topicName>/rot_laser_scan</topicName>
          <frameName>rot_laser_link</frameName>
        </plugin>

    </sensor>
  </gazebo>

</robot>

